Workbook

Sheet 試験項目一覧
A1: No. | B1: 試験ID | C1: 対象 | D1: 対象ドキュメント箇所 | E1: 分類 | F1: 試験項目 | G1: なぜ必要か | H1: 前提条件 | I1: 手順 | J1: 期待結果 | K1: 確認箇所 | L1: 復旧確認 | M1: 優先順位 | N1: 実施可否（暫定） | O1: 必要手段・環境 | P1: 要仕様確認事項 | Q1: 備考 | R1: 実施結果 | S1: 判定
A2: 1 | B2: B-001 | C2: B | D2: 図B：ULAgent Sender／指定フォルダ監視・対象3ファイル取得 | E2: 欠損 | F2: SAMPLINGファイルのみ未生成 | G2: 3ファイル前提の処理で欠損時の誤送信・待ち続け・取りこぼしを防ぐため。 | H2: 監視フォルダは正常。残り2種のファイルは正常に配置する。 | I2: 1) SAMPLINGのみ配置しない。 2) 監視周期を跨ぐまで待つ。 3) Sender状態・履歴・ログを確認する。 | J2: 欠損ファイルを正常取得扱いにせず、存在するファイルの扱いが仕様どおりである。異常や待機状態が識別可能である。 | K2: Sender状態、SQLite、Serilog、監視フォルダ | L2: 異常条件を解除後、通常処理へ復帰することを確認する。 | M2: P1 | N2: 実施可 | P2: 3ファイルを1セットとして扱うか、各ファイル独立処理か。
A3: 2 | B3: B-002 | C3: B | D3: 図B：ULAgent Sender／指定フォルダ監視・対象3ファイル取得 | E3: 欠損 | F3: EVENTファイルのみ未生成 | G3: 3ファイル前提の処理で欠損時の誤送信・待ち続け・取りこぼしを防ぐため。 | H3: 監視フォルダは正常。残り2種のファイルは正常に配置する。 | I3: 1) EVENTのみ配置しない。 2) 監視周期を跨ぐまで待つ。 3) Sender状態・履歴・ログを確認する。 | J3: 欠損ファイルを正常取得扱いにせず、存在するファイルの扱いが仕様どおりである。異常や待機状態が識別可能である。 | K3: Sender状態、SQLite、Serilog、監視フォルダ | L3: 異常条件を解除後、通常処理へ復帰することを確認する。 | M3: P1 | N3: 実施可 | P3: 3ファイルを1セットとして扱うか、各ファイル独立処理か。
A4: 3 | B4: B-003 | C4: B | D4: 図B：ULAgent Sender／指定フォルダ監視・対象3ファイル取得 | E4: 欠損 | F4: PROCESSファイルのみ未生成 | G4: 3ファイル前提の処理で欠損時の誤送信・待ち続け・取りこぼしを防ぐため。 | H4: 監視フォルダは正常。残り2種のファイルは正常に配置する。 | I4: 1) PROCESSのみ配置しない。 2) 監視周期を跨ぐまで待つ。 3) Sender状態・履歴・ログを確認する。 | J4: 欠損ファイルを正常取得扱いにせず、存在するファイルの扱いが仕様どおりである。異常や待機状態が識別可能である。 | K4: Sender状態、SQLite、Serilog、監視フォルダ | L4: 異常条件を解除後、通常処理へ復帰することを確認する。 | M4: P1 | N4: 実施可 | P4: 3ファイルを1セットとして扱うか、各ファイル独立処理か。
A5: 4 | B5: B-004 | C5: B | D5: 図B：ULAgent Sender／指定フォルダ監視・対象3ファイル取得 | E5: 到着順 | F5: 3ファイルを通常と異なる順番で配置 | G5: ファイル生成順に依存していると取りこぼしや誤関連付けが起きるため。 | H5: 3種類の正常ファイルを準備する。 | I5: 1) PROCESS→EVENT→SAMPLINGの順に時間差で配置。 2) 全ファイル取得まで待つ。 3) 履歴を確認。 | J5: 到着順に依存せず対象ファイルを正しく認識し、重複・欠落なく処理する。 | K5: 監視フォルダ、Sender SQLite、Serilog | L5: 異常条件を解除後、通常処理へ復帰することを確認する。 | M5: P1 | N5: 実施可
A6: 5 | B6: B-005 | C6: B | D6: 図B：ULAgent Sender／指定フォルダ監視・対象3ファイル取得 | E6: 遅延 | F6: 1ファイルだけ大幅に遅れて配置 | G6: 生成遅延時の待機・タイムアウト・後追い取得を確認するため。 | H6: 2ファイルを先に配置する。 | I6: 1) 2ファイル配置。 2) 複数監視周期後に残り1ファイルを配置。 3) 取得状況を確認。 | J6: 遅延ファイルが後から正しく取得され、先行ファイルとの状態整合が崩れない。 | K6: Sender SQLite、Serilog、監視フォルダ | L6: 異常条件を解除後、通常処理へ復帰することを確認する。 | M6: P1 | N6: 実施可 | P6: セット待機時間・タイムアウト仕様。
A7: 6 | B7: B-006 | C7: B | D7: 図B：ULAgent Sender／指定フォルダ監視・対象3ファイル取得 | E7: 異常入力 | F7: 書込み途中のファイルを検出 | G7: 生成中ファイルを取得すると欠損データ送信につながるため。 | H7: Sender監視が稼働している。 | I7: 1) 大きなファイルを低速で監視フォルダへ書込む。 2) 書込み中に監視周期を跨ぐ。 3) 取得開始有無を確認。 | J7: 書込み完了前のファイルを確定ファイルとして扱わない、または仕様どおり安全に扱う。 | K7: 監視フォルダ、Sender状態、SQLite、Serilog | L7: 異常条件を解除後、通常処理へ復帰することを確認する。 | M7: P1 | N7: 条件付き | O7: 低速コピー/生成スクリプト | P7: ファイル完成判定方式。
A8: 7 | B8: B-007 | C8: B | D8: 図B：ULAgent Sender／指定フォルダ監視・対象3ファイル取得 | E8: 異常入力 | F8: 0 byteファイル | G8: 空ファイルを正常データとして扱わないことを確認するため。 | H8: Sender監視が稼働している。 | I8: 1) 対象名の0 byteファイルを配置。 2) 監視周期後の処理を確認。 | J8: 0 byteを正常データとして誤登録せず、異常または対象外として識別できる。 | K8: 監視フォルダ、Sender状態、SQLite、Serilog | L8: 異常条件を解除後、通常処理へ復帰することを確認する。 | M8: P1 | N8: 実施可 | P8: 0 byte許容有無。
A9: 8 | B9: B-008 | C9: B | D9: 図B：ULAgent Sender／指定フォルダ監視・対象3ファイル取得 | E9: 異常入力 | F9: 極端に小さい不完全ファイル | G9: 形式上は存在するが内容不足のケースを確認するため。 | H9: Sender監視が稼働している。 | I9: 1) ヘッダのみ等の短いファイルを配置。 2) 取得・後続処理を確認。 | J9: 不完全データが正常完了扱いにならず、後続で失敗しても状態が追跡可能である。 | K9: 監視フォルダ、Sender状態、SQLite、Serilog | L9: 異常条件を解除後、通常処理へ復帰することを確認する。 | M9: P2 | N9: 実施可 | P9: Senderが内容検証する範囲。
A10: 9 | B10: B-009 | C10: B | D10: 図B：ULAgent Sender／指定フォルダ監視・対象3ファイル取得 | E10: 異常入力 | F10: 大容量ファイル | G10: サイズ増大時の読込・転送準備・メモリ消費を確認するため。 | H10: Sender監視が稼働している。 | I10: 1) 想定最大付近またはそれ以上のファイルを配置。 2) 取得時間と状態を確認。 | J10: ハング・異常終了せず、上限超過時は明確に失敗扱いとなる。 | K10: 監視フォルダ、Sender状態、SQLite、Serilog | L10: 異常条件を解除後、通常処理へ復帰することを確認する。 | M10: P1 | N10: 条件付き | O10: 大容量テストファイル | P10: 最大ファイルサイズ。
A11: 10 | B11: B-010 | C11: B | D11: 図B：ULAgent Sender／指定フォルダ監視・対象3ファイル取得 | E11: 異常入力 | F11: ファイル名不正 | G11: 監視対象判定の誤検知を防ぐため。 | H11: Sender監視が稼働している。 | I11: 1) 命名規則から1文字ずらしたファイルを配置。 2) 取得有無を確認。 | J11: 対象外ファイルを誤取得しない。 | K11: 監視フォルダ、Sender状態、SQLite、Serilog | L11: 異常条件を解除後、通常処理へ復帰することを確認する。 | M11: P2 | N11: 実施可 | P11: 正式な命名規則。
A12: 11 | B12: B-011 | C12: B | D12: 図B：ULAgent Sender／指定フォルダ監視・対象3ファイル取得 | E12: 異常入力 | F12: 拡張子不正 | G12: 誤形式ファイルの取り込みを防ぐため。 | H12: Sender監視が稼働している。 | I12: 1) 正しいベース名で拡張子のみ変更。 2) 取得有無を確認。 | J12: 対象外として扱い、正常対象へ影響しない。 | K12: 監視フォルダ、Sender状態、SQLite、Serilog | L12: 異常条件を解除後、通常処理へ復帰することを確認する。 | M12: P2 | N12: 実施可 | P12: 許容拡張子一覧。
A13: 12 | B13: B-012 | C13: B | D13: 図B：ULAgent Sender／指定フォルダ監視・対象3ファイル取得 | E13: 異常入力 | F13: 同名ファイル再配置 | G13: 再生成・再投入時の重複処理を確認するため。 | H13: Sender監視が稼働している。 | I13: 1) 一度処理済みの同名ファイルを再配置。 2) 再取得・履歴を確認。 | J13: 重複送信の扱いが仕様どおりで、履歴が矛盾しない。 | K13: 監視フォルダ、Sender状態、SQLite、Serilog | L13: 異常条件を解除後、通常処理へ復帰することを確認する。 | M13: P1 | N13: 実施可 | P13: 重複判定キー。
A14: 13 | B14: B-013 | C14: B | D14: 図B：ULAgent Sender／指定フォルダ監視・対象3ファイル取得 | E14: 異常入力 | F14: 想定外ファイル混在 | G14: 監視フォルダのノイズに対する耐性確認のため。 | H14: Sender監視が稼働している。 | I14: 1) txt/tmp/bak等を正常3ファイルと同時配置。 2) 処理確認。 | J14: 想定外ファイルを無視し、正常対象だけ処理する。 | K14: 監視フォルダ、Sender状態、SQLite、Serilog | L14: 異常条件を解除後、通常処理へ復帰することを確認する。 | M14: P2 | N14: 実施可 | P14: 無視対象・エラー対象の規定。
A15: 14 | B15: B-014 | C15: B | D15: 図B：ULAgent Sender／指定フォルダ監視・対象3ファイル取得 | E15: 異常入力 | F15: ファイルロック中 | G15: 他プロセス使用中のアクセス失敗時挙動を確認するため。 | H15: Sender監視が稼働している。 | I15: 1) 対象ファイルを排他ロック。 2) 監視周期を跨ぐ。 3) ロック解除後も確認。 | J15: 異常終了やファイル破損を起こさず、解除後に再取得できる。 | K15: 監視フォルダ、Sender状態、SQLite、Serilog | L15: 異常条件を解除後、通常処理へ復帰することを確認する。 | M15: P1 | N15: 条件付き | O15: 排他ロック用ツール/スクリプト | P15: 再試行間隔・回数。
A16: 15 | B16: B-015 | C16: B | D16: 図B：ULAgent Sender／指定フォルダ監視・対象3ファイル取得 | E16: 異常入力 | F16: 読取権限なし | G16: アクセス権異常時の例外処理確認のため。 | H16: Sender監視が稼働している。 | I16: 1) 対象ファイルの読取権限を外す。 2) 取得を待つ。 3) 権限復旧。 | J16: アクセス失敗を識別可能に記録し、プロセスが不正終了しない。 | K16: 監視フォルダ、Sender状態、SQLite、Serilog | L16: 異常条件を解除後、通常処理へ復帰することを確認する。 | M16: P1 | N16: 条件付き | O16: OS権限変更 | P16: サービス実行ユーザー権限。
A17: 16 | B17: B-016 | C17: B | D17: 図B：ULAgent Sender／指定フォルダ監視・対象3ファイル取得 | E17: 異常入力 | F17: 監視フォルダ不存在 | G17: 設定先削除・マウント切れなどを想定するため。 | H17: Sender監視が稼働している。 | I17: 1) Sender停止中に監視フォルダをリネーム/削除。 2) Sender起動。 3) 状態確認。 | J17: フォルダ不存在を検出し、無限例外や異常終了を起こさない。 | K17: 監視フォルダ、Sender状態、SQLite、Serilog | L17: 異常条件を解除後、通常処理へ復帰することを確認する。 | M17: P1 | N17: 条件付き | O17: フォルダ操作権限 | P17: 自動再作成の有無。
A18: 17 | B18: B-017 | C18: B | D18: 図B：ULAgent Sender／指定フォルダ監視・対象3ファイル取得 | E18: 異常入力 | F18: 監視フォルダアクセス拒否 | G18: フォルダ権限変更時の挙動確認のため。 | H18: Sender監視が稼働している。 | I18: 1) フォルダの読取権限を拒否。 2) 監視周期を跨ぐ。 3) 復旧。 | J18: アクセス拒否を明確に扱い、復旧後に監視を再開できる。 | K18: 監視フォルダ、Sender状態、SQLite、Serilog | L18: 異常条件を解除後、通常処理へ復帰することを確認する。 | M18: P1 | N18: 条件付き | O18: OS権限変更 | P18: 監視再開仕様。
A19: 18 | B19: B-018 | C19: B | D19: 図B：ULAgent Sender／指定フォルダ監視・対象3ファイル取得 | E19: 異常入力 | F19: 大量ファイル一括投入 | G19: 短時間に多数生成された際の取りこぼし・キュー滞留を確認するため。 | H19: Sender監視が稼働している。 | I19: 1) 多数セットを一括配置。 2) 全件処理数を照合。 3) 処理時間・負荷確認。 | J19: 欠落・重複なく処理し、処理不能時は明確な状態が残る。 | K19: 監視フォルダ、Sender状態、SQLite、Serilog | L19: 異常条件を解除後、通常処理へ復帰することを確認する。 | M19: P1 | N19: 条件付き | O19: 大量データ生成 | P19: 同時/最大キュー数。
A20: 19 | B20: B-019 | C20: B | D20: 図B：ULAgent Sender／指定フォルダ監視・対象3ファイル取得 | E20: 異常入力 | F20: 取得直前にファイル削除 | G20: 検出後と読込開始の競合を確認するため。 | H20: Sender監視が稼働している。 | I20: 1) 検出タイミングに合わせファイルを削除。 2) 例外・再試行を確認。 | J20: FileNotFound等で異常終了せず、状態が識別可能である。 | K20: 監視フォルダ、Sender状態、SQLite、Serilog | L20: 異常条件を解除後、通常処理へ復帰することを確認する。 | M20: P1 | N20: 条件付き | O20: タイミング制御スクリプト | P20: 再試行仕様。
A21: 20 | B21: B-020 | C21: B | D21: 図B：ULAgent Sender／指定フォルダ監視・対象3ファイル取得 | E21: 異常入力 | F21: 取得中にファイル置換 | G21: TOCTOU競合で別内容を送信しないことを確認するため。 | H21: Sender監視が稼働している。 | I21: 1) 読込中に同名ファイルを置換。 2) 送信内容・履歴を確認。 | J21: 破損・内容混在を起こさず、一貫したファイル単位で扱う。 | K21: 監視フォルダ、Sender状態、SQLite、Serilog | L21: 異常条件を解除後、通常処理へ復帰することを確認する。 | M21: P1 | N21: 条件付き | O21: 大容量ファイル/置換スクリプト | P21: ファイル占有・コピー方式。
A22: 21 | B22: B-021 | C22: B | D22: 図B：ULAgent Sender／指定フォルダ監視・対象3ファイル取得 | E22: 異常入力 | F22: 長いファイル名/パス | G22: OSパス長境界で例外になる可能性があるため。 | H22: Sender監視が稼働している。 | I22: 1) 許容範囲付近までパス/名称を長くする。 2) 取得を確認。 | J22: サポート範囲内は正常処理し、範囲外は明確に失敗する。 | K22: 監視フォルダ、Sender状態、SQLite、Serilog | L22: 異常条件を解除後、通常処理へ復帰することを確認する。 | M22: P3 | N22: 条件付き | O22: 長いパス生成 | P22: 最大パス長。
A23: 22 | B23: C-001 | C23: C | D23: 図C：TLS gRPC通信／Sender→Receiverファイル転送 | E23: 接続異常 | F23: Receiver停止状態で送信開始 | G23: 送信先停止時の失敗検知・再送を確認するため。 | H23: Sender/Receiverは通常時に通信可能。 | I23: 1) Receiverサービスを停止して対象ファイルを配置する。 2) Sender/Receiverの状態・履歴・ログを確認。 3) 必要に応じ復旧して再送確認。 | J23: 接続失敗が検知され、送信済み誤判定をせず、再試行/失敗状態が追跡可能。 | K23: Sender/Receiverログ、Sender SQLite、Receiver受信状態 | L23: 異常条件を解除後、通常処理へ復帰することを確認する。 | M23: P1 | N23: 実施可 | O23: Receiverサービス操作 | P23: 再試行回数・間隔
A24: 23 | B24: C-002 | C24: C | D24: 図C：TLS gRPC通信／Sender→Receiverファイル転送 | E24: ネットワーク | F24: 送信開始前にネットワーク切断 | G24: 通信経路断時にデータを失わないことを確認するため。 | H24: Sender/Receiverは通常時に通信可能。 | I24: 1) ネットワークを切断後に対象ファイルを配置する。 2) Sender/Receiverの状態・履歴・ログを確認。 3) 必要に応じ復旧して再送確認。 | J24: 送信成功扱いにせず、復旧後に仕様どおり再送可能。 | K24: Sender/Receiverログ、Sender SQLite、Receiver受信状態 | L24: 異常条件を解除後、通常処理へ復帰することを確認する。 | M24: P1 | N24: 条件付き | O24: NIC無効化/Firewall | P24: 再送条件
A25: 24 | B25: C-003 | C25: C | D25: 図C：TLS gRPC通信／Sender→Receiverファイル転送 | E25: ネットワーク | F25: 送信途中でネットワーク切断 | G25: 部分送信時の整合性を確認するため。 | H25: Sender/Receiverは通常時に通信可能。 | I25: 1) 大容量ファイル送信中にNIC無効化または通信遮断する。 2) Sender/Receiverの状態・履歴・ログを確認。 3) 必要に応じ復旧して再送確認。 | J25: Receiver側に不完全ファイルを正常登録せず、Sender側も成功扱いにしない。 | K25: Sender/Receiverログ、Sender SQLite、Receiver受信状態 | L25: 異常条件を解除後、通常処理へ復帰することを確認する。 | M25: P1 | N25: 条件付き | O25: 大容量ファイル/NIC制御 | P25: 中断ファイルの後処理
A26: 25 | B26: C-004 | C26: C | D26: 図C：TLS gRPC通信／Sender→Receiverファイル転送 | E26: 応答欠落 | F26: Receiver受信後・ACK相当前に通信断 | G26: 受信済みだがSenderが成功を認識できない場合の重複を確認するため。 | H26: Sender/Receiverは通常時に通信可能。 | I26: 1) 受信完了直後を狙って通信を遮断し、復旧後の再送を確認する。 2) Sender/Receiverの状態・履歴・ログを確認。 3) 必要に応じ復旧して再送確認。 | J26: 再送されても重複登録/重複表示が仕様どおり防止または識別される。 | K26: Sender/Receiverログ、Sender SQLite、Receiver受信状態 | L26: 異常条件を解除後、通常処理へ復帰することを確認する。 | M26: P1 | N26: 条件付き | O26: ネットワーク制御/ログ時刻照合 | P26: ACK/重複排除方式
... A39: 38 | B39: C-017 | C39: C | D39: 図C：TLS gRPC通信／Sender→Receiverファイル転送 | E39: 再起動 | F39: Receiver受信中にプロセス再起動 | G39: 受信途中ファイルの扱いを確認するため。 | H39: Sender/Receiverは通常時に通信可能。 | I39: 1) 送信中にReceiverを停止/再起動する。 2) Sender/Receiverの状態・履歴・ログを確認。 3) 必要に応じ復旧して再送確認。 | J39: 不完全受信を正常完了扱いせず、再送後に整合する。 | K39: Sender/Receiverログ、Sender SQLite、Receiver受信状態 | L39: 異常条件を解除後、通常処理へ復帰することを確認する。 | M39: P1 | N39: 条件付き | O39: サービス制御 | P39: 一時ファイル管理
A40: 39 | B40: C-018 | C40: C | D40: 図C：TLS gRPC通信／Sender→Receiverファイル転送 | E40: 並行 | F40: 3ファイル同時送信 | G40: 並行処理時の順序・競合を確認するため。 | H40: Sender/Receiverは通常時に通信可能。 | I40: 1) 3種類を同時に送信対象へ投入する。 2) Sender/Receiverの状態・履歴・ログを確認。 3) 必要に応じ復旧して再送確認。 | J40: 欠落・混在・状態競合なく各ファイルを識別して送信する。 | K40: Sender/Receiverログ、Sender SQLite、Receiver受信状態 | L40: 異常条件を解除後、通常処理へ復帰することを確認する。 | M40: P1 | N40: 実施可 | P40: 並列度
A41: 40 | B41: C-019 | C41: C | D41: 図C：TLS gRPC通信／Sender→Receiverファイル転送 | E41: 並行 | F41: 大量ファイル連続送信 | G41: キュー滞留・接続枯渇を確認するため。 | H41: Sender/Receiverは通常時に通信可能。 | I41: 1) 多数ファイルを短時間に投入し継続送信する。 2) Sender/Receiverの状態・履歴・ログを確認。 3) 必要に応じ復旧して再送確認。 | J41: キューが破綻せず、処理不能時も状態が明確。 | K41: Sender/Receiverログ、Sender SQLite、Receiver受信状態 | L41: 異常条件を解除後、通常処理へ復帰することを確認する。 | M41: P1 | N41: 条件付き | O41: 大量データ | P41: 最大キュー/並列数
A42: 41 | B42: C-020 | C42: C | D42: 図C：TLS gRPC通信／Sender→Receiverファイル転送 | E42: 整合性 | F42: 送信ファイル内容を途中で改変 | G42: 送信元内容の一貫性を確認するため。 | H42: Sender/Receiverは通常時に通信可能。 | I42: 1) 大容量ファイル送信中に元ファイルの改変を試行する。 2) Sender/Receiverの状態・履歴・ログを確認。 3) 必要に応じ復旧して再送確認。 | J42: 受信データが混在/破損しない。 | K42: Sender/Receiverログ、Sender SQLite、Receiver受信状態 | L42: 異常条件を解除後、通常処理へ復帰することを確認する。 | M42: P1 | N42: 条件付き | O42: ファイル改変スクリプト | P42: 送信時スナップショット方式
A43: 42 | B43: C-021 | C43: C | D43: 図C：TLS gRPC通信／Sender→Receiverファイル転送 | E43: 上限 | F43: gRPCメッセージ/ストリーム上限超過 | G43: サイズ制限時の明確な失敗を確認するため。 | H43: Sender/Receiverは通常時に通信可能。 | I43: 1) 設定上限を超えるファイルを送信する。 2) Sender/Receiverの状態・履歴・ログを確認。 3) 必要に応じ復旧して再送確認。 | J43: 上限超過が明確に失敗扱いとなり、再送ループしない。 | K43: Sender/Receiverログ、Sender SQLite、Receiver受信状態 | L43: 異常条件を解除後、通常処理へ復帰することを確認する。 | M43: P1 | N43: 条件付き | O43: 大容量ファイル | P43: gRPC最大サイズ
A44: 43 | B44: C-022 | C44: C | D44: 図C：TLS gRPC通信／Sender→Receiverファイル転送 | E44: 互換性 | F44: Sender/Receiver設定・バージョン不整合 | G44: 将来の更新差分で不正処理しないため。 | H44: Sender/Receiverは通常時に通信可能。 | I44: 1) 可能ならバージョン/設定差を意図的に作る。 2) Sender/Receiverの状態・履歴・ログを確認。 3) 必要に応じ復旧して再送確認。 | J44: 非互換時は安全に失敗し、誤解釈しない。 | K44: Sender/Receiverログ、Sender SQLite、Receiver受信状態 | L44: 異常条件を解除後、通常処理へ復帰することを確認する。 | M44: P3 | N44: 条件付き | O44: 異なるビルド/設定 | P44: 互換性ポリシー
A45: 44 | B45: D-001 | C45: D | D45: 図D：Sender側SQLite／送信状態・履歴管理 | E45: DBアクセス | F45: SQLiteファイルが存在しない | G45: DB再生成/異常検知の仕様を確認するため。 | H45: SenderのSQLiteをバックアップ済み。 | I45: 1) SQLiteを退避してSenderを起動/処理。 2) DB内容・Senderログ・送信実態を照合。 3) 復旧後の状態を確認。 | J45: DB不存在時の挙動が仕様どおりで、送信履歴を誤記録しない。 | K45: Sender SQLite、Sender Serilog、Receiver受信実態 | L45: 異常条件を解除後、通常処理へ復帰することを確認する。 | M45: P1 | N45: 条件付き | O45: DBバックアップ | P45: 自動生成有無
A46: 45 | B46: D-002 | C46: D | D46: 図D：Sender側SQLite／送信状態・履歴管理 | E46: DBアクセス | F46: SQLiteを読取専用にする | G46: 状態更新不能時の処理を確認するため。 | H46: SenderのSQLiteをバックアップ済み。 | I46: 1) DBファイルを読取専用化して送信。 2) DB内容・Senderログ・送信実態を照合。 3) 復旧後の状態を確認。 | J46: 更新失敗を検出し、送信状態とDB状態が不整合のまま隠れない。 | K46: Sender SQLite、Sender Serilog、Receiver受信実態 | L46: 異常条件を解除後、通常処理へ復帰することを確認する。 | M46: P1 | N46: 条件付き | O46: ファイル属性/ACL | P46: DB更新失敗時の送信継続可否
A47: 46 | B47: D-003 | C47: D | D47: 図D：Sender側SQLite／送信状態・履歴管理 | E47: DBロック | F47: SQLite排他ロック | G47: ロック競合時のタイムアウト/再試行確認。 | H47: SenderのSQLiteをバックアップ済み。 | I47: 1) 別プロセスでDBをロック中に送信。 2) DB内容・Senderログ・送信実態を照合。 3) 復旧後の状態を確認。 | J47: 無限待ちせず、再試行または明確に失敗する。 | K47: Sender SQLite、Sender Serilog、Receiver受信実態 | L47: 異常条件を解除後、通常処理へ復帰することを確認する。 | M47: P1 | N47: 条件付き | O47: SQLiteロック用ツール | P47: busy timeout
A48: 47 | B48: D-004 | C48: D | D48: 図D：Sender側SQLite／送信状態・履歴管理 | E48: DB破損 | F48: SQLiteファイル破損 | G48: 破損DBで履歴を失わず安全停止できるか確認。 | H48: SenderのSQLiteをバックアップ済み。 | I48: 1) コピーしたDBを意図的に破損して起動。 2) DB内容・Senderログ・送信実態を照合。 3) 復旧後の状態を確認。 | J48: 破損を検出し、不正な更新やクラッシュループを起こさない。 | K48: Sender SQLite、Sender Serilog、Receiver受信実態 | L48: 異常条件を解除後、通常処理へ復帰することを確認する。 | M48: P1 | N48: 条件付き | O48: DBバックアップ/破損コピー | P48: 破損時復旧方法
A49: 48 | B49: D-005 | C49: D | D49: 図D：Sender側SQLite／送信状態・履歴管理 | E49: 容量 | F49: ディスク空き容量不足 | G49: DB書込途中の失敗・OS影響を確認するため。 | H49: SenderのSQLiteをバックアップ済み。 | I49: 1) DB配置ディスクを安全なテスト方法で容量逼迫させる。 2) DB内容・Senderログ・送信実態を照合。 3) 復旧後の状態を確認。 | J49: 書込失敗が識別でき、DBが破損しない。 | K49: Sender SQLite、Sender Serilog、Receiver受信実態 | L49: 異常条件を解除後、通常処理へ復帰することを確認する。 | M49: P1 | N49: 条件付き | O49: 容量制限可能なテスト環境 | P49: 最低空き容量
A50: 49 | B50: D-006 | C50: D | D50: 図D：Sender側SQLite／送信状態・履歴管理 | E50: トランザクション | F50: 状態更新途中にSender強制終了 | G50: 原子性・再起動時整合性を確認するため。 | H50: SenderのSQLiteをバックアップ済み。 | I50: 1) DB更新タイミングでSenderを強制停止。 2) DB内容・Senderログ・送信実態を照合。 3) 復旧後の状態を確認。 | J50: 中途半端な状態を残さず、再起動時に未完了を識別できる。 | K50: Sender SQLite、Sender Serilog、Receiver受信実態 | L50: 異常条件を解除後、通常処理へ復帰することを確認する。 | M50: P1 | N50: 条件付き | O50: プロセス制御 | P50: トランザクション境界
A51: 50 | B51: D-007 | C51: D | D51: 図D：Sender側SQLite／送信状態・履歴管理 | E51: 重複 | F51: 同一ファイルの履歴重複登録 | G51: 再送時の履歴重複/一意性確認。 | H51: SenderのSQLiteをバックアップ済み。 | I51: 1) 同一ファイルを再送させDBレコードを確認。 2) DB内容・Senderログ・送信実態を照合。 3) 復旧後の状態を確認。 | J51: 履歴が仕様どおり追記/更新され、矛盾しない。 | K51: Sender SQLite、Sender Serilog、Receiver受信実態 | L51: 異常条件を解除後、通常処理へ復帰することを確認する。 | M51: P1 | N51: 実施可 | P51: 一意キー/履歴方式
A52: 51 | B52: D-008 | C52: D | D52: 図D：Sender側SQLite／送信状態・履歴管理 | E52: 状態遷移 | F52: 送信失敗→再送成功 | G52: 状態遷移の正確性確認。 | H52: SenderのSQLiteをバックアップ済み。 | I52: 1) 一度通信失敗させ、その後復旧し再送成功させる。 2) DB内容・Senderログ・送信実態を照合。 3) 復旧後の状態を確認。 | J52: 失敗→再送→成功の履歴/最終状態が追跡可能。 | K52: Sender SQLite、Sender Serilog、Receiver受信実態 | L52: 異常条件を解除後、通常処理へ復帰することを確認する。 | M52: P1 | N52: 実施可 | P52: 状態遷移定義
...

Sheet 集計
A1: 対象 | B1: 項目数 | C1: P1件数 | D1: 条件付き/要仕様確認件数
A2: B | B2: =COUNTIF(試験項目一覧!$C$2:$C$153,A2) -> 21 | C2: =COUNTIFS(試験項目一覧!$C$2:$C$153,A2,試験項目一覧!$M$2:$M$153,"P1") -> 16 | D2: =COUNTIFS(試験項目一覧!$C$2:$C$153,A2,試験項目一覧!$N$2:$N$153,"<>実施可") -> 10
A3: C | B3: =COUNTIF(試験項目一覧!$C$2:$C$153,A3) -> 22 | C3: =COUNTIFS(試験項目一覧!$C$2:$C$153,A3,試験項目一覧!$M$2:$M$153,"P1") -> 18 | D3: =COUNTIFS(試験項目一覧!$C$2:$C$153,A3,試験項目一覧!$N$2:$N$153,"<>実施可") -> 20
A4: D | B4: =COUNTIF(試験項目一覧!$C$2:$C$153,A4) -> 15 | C4: =COUNTIFS(試験項目一覧!$C$2:$C$153,A4,試験項目一覧!$M$2:$M$153,"P1") -> 11 | D4: =COUNTIFS(試験項目一覧!$C$2:$C$153,A4,試験項目一覧!$N$2:$N$153,"<>実施可") -> 12
A5: E | B5: =COUNTIF(試験項目一覧!$C$2:$C$153,A5) -> 10 | C5: =COUNTIFS(試験項目一覧!$C$2:$C$153,A5,試験項目一覧!$M$2:$M$153,"P1") -> 4 | D5: =COUNTIFS(試験項目一覧!$C$2:$C$153,A5,試験項目一覧!$N$2:$N$153,"<>実施可") -> 8
A6: F | B6: =COUNTIF(試験項目一覧!$C$2:$C$153,A6) -> 12 | C6: =COUNTIFS(試験項目一覧!$C$2:$C$153,A6,試験項目一覧!$M$2:$M$153,"P1") -> 4 | D6: =COUNTIFS(試験項目一覧!$C$2:$C$153,A6,試験項目一覧!$N$2:$N$153,"<>実施可") -> 12
A7: G | B7: =COUNTIF(試験項目一覧!$C$2:$C$153,A7) -> 18 | C7: =COUNTIFS(試験項目一覧!$C$2:$C$153,A7,試験項目一覧!$M$2:$M$153,"P1") -> 15 | D7: =COUNTIFS(試験項目一覧!$C$2:$C$153,A7,試験項目一覧!$N$2:$N$153,"<>実施可") -> 14
A8: H | B8: =COUNTIF(試験項目一覧!$C$2:$C$153,A8) -> 14 | C8: =COUNTIFS(試験項目一覧!$C$2:$C$153,A8,試験項目一覧!$M$2:$M$153,"P1") -> 11 | D8: =COUNTIFS(試験項目一覧!$C$2:$C$153,A8,試験項目一覧!$N$2:$N$153,"<>実施可") -> 11
A9: I | B9: =COUNTIF(試験項目一覧!$C$2:$C$153,A9) -> 8 | C9: =COUNTIFS(試験項目一覧!$C$2:$C$153,A9,試験項目一覧!$M$2:$M$153,"P1") -> 4 | D9: =COUNTIFS(試験項目一覧!$C$2:$C$153,A9,試験項目一覧!$N$2:$N$153,"<>実施可") -> 6
A10: J | B10: =COUNTIF(試験項目一覧!$C$2:$C$153,A10) -> 10 | C10: =COUNTIFS(試験項目一覧!$C$2:$C$153,A10,試験項目一覧!$M$2:$M$153,"P1") -> 5 | D10: =COUNTIFS(試験項目一覧!$C$2:$C$153,A10,試験項目一覧!$N$2:$N$153,"<>実施可") -> 10
A11: K | B11: =COUNTIF(試験項目一覧!$C$2:$C$153,A11) -> 22 | C11: =COUNTIFS(試験項目一覧!$C$2:$C$153,A11,試験項目一覧!$M$2:$M$153,"P1") -> 12 | D11: =COUNTIFS(試験項目一覧!$C$2:$C$153,A11,試験項目一覧!$N$2:$N$153,"<>実施可") -> 16
A13: 全試験項目数 | B13: 152
A14: 横断シナリオ数 | B14: 15
A15: 正常系 | B15: 既完了の前提
A16: A/L | B16: A対象外、L今回対象外

Sheet 対象定義
A1: 記号 | B1: 対象/対象外 | C1: 構成要素 | D1: 今回の評価方針 | F1: 判定値 | G1: 意味
A2: A | B2: 対象外 | C2: 装置/テストデータ生成 | D2: 完成済みのため評価対象外 | F2: 実施可 | G2: 一般的な操作だけで再現可能
A3: B | B3: 対象 | C3: Sender：指定フォルダ監視・3ファイル取得 | D3: 欠損、遅延、競合、権限、容量、境界 | F3: 条件付き | G3: 権限変更、サービス停止、負荷/通信制御等が必要
A4: C | B4: 対象 | C4: TLS gRPC送信 | D4: 通信断、TLS、再送、タイムアウト、再起動、並行 | F4: 要仕様確認 | G4: テストフックや内部仕様が不明で、現時点では可否確定不可
A5: D | B5: 対象 | C5: Sender SQLite | D5: DBロック/破損/容量/状態遷移/復旧
A6: E | B6: 対象 | C6: Sender Serilog | D6: ログ出力失敗、ローテーション、追跡性 | F6: 優先順位 | G6: 基準
A7: F | B7: 対象 | C7: CTC側OS状態取得 | D7: 高負荷、取得失敗、時刻、継続性 | F7: P1 | G7: データ欠落/重複、DB不整合、クラッシュ、復旧不能、TLS等の重大障害
A8: G | B8: 対象 | C8: Receiver：ファイル受信 | D8: 部分受信、重複、容量、権限、再起動、後段障害 | F8: P2 | G8: 性能劣化、ログ/監視の欠落、一時障害、表示整合
A9: H | B9: 対象 | C9: Receiver SQLite/DB登録状態 | D9: 状態遷移、不整合、重複、DB障害、復旧 | F9: P3 | G9: 低頻度の境界値、特殊文字、互換性等
A10: I | B10: 対象 | C10: Receiver Serilog | D10: ログ出力失敗、ローテーション、追跡性
A11: J | B11: 対象 | C11: Receiver側OS状態取得 | D11: 高負荷、取得失敗、処理時間への影響
A12: K | B12: 対象 | C12: ULsight画面表示 | D12: 欠損、重複、遅延、時刻、境界、大量、DB障害、復旧
A13: L | B13: 今回対象外 | C13: ULsight側リソース測定 | D13: 必要なら同じ方針で追加可能

Sheet 横断シナリオ
A1: ID | B1: 対象 | C1: 横断シナリオ | D1: 目的 | E1: 前提/手順 | F1: 期待結果 | G1: 優先順位 | H1: 実施可否（暫定）
A2: X-001 | B2: B→C→D→E | C2: ファイル検出直後にネットワーク断 | D2: 取得済みだが未送信のデータ保持確認 | E2: 対象3ファイル配置→Bで検出後に通信断→復旧 | F2: 未送信分が失われず、履歴/ログが整合して再送される | G2: P1 | H2: 条件付き
A3: X-002 | B3: C→G→H | C3: 受信完了直後にReceiver停止 | D3: ACK/状態更新境界の重複確認 | E3: 大容量送信→受信完了付近でReceiver停止→再起動 | F3: 再送時もDB重複がなく最終状態が整合する | G3: P1 | H3: 条件付き
A4: X-003 | B4: G→H→K | C4: 受信成功・DB停止 | D4: 受信と登録の分離/復旧確認 | E4: DB停止→受信→DB復旧→再登録→画面確認 | F4: データを失わず、復旧後に1件だけ正しく表示 | G4: P1 | H4: 条件付き
A5: X-004 | B5: D/E/F | C5: Sender側ディスク容量不足 | D5: SQLite/ログ/OS測定が同一障害で影響する場合の確認 | E5: 安全なテスト領域で容量逼迫→送信実行 | F5: 状態不明・DB破損を起こさず障害箇所を特定可能 | G5: P1 | H5: 条件付き
A6: X-005 | B6: H/I/J | C6: Receiver側ディスク容量不足 | D6: 状態DB/ログ/OS測定の複合影響確認 | E6: 受信処理中に安全な容量不足を発生 | F6: 受信/登録の成否が追跡可能で復旧後に整合する | G6: P1 | H6: 条件付き
A7: X-006 | B7: B→K | C7: 同一3ファイルセットを再投入 | D7: E2Eの重複排除/表示確認 | E7: 一度完了した同一セットを再投入 | F7: 履歴と画面が重複仕様どおりで、意図しない二重登録なし | G7: P1 | H7: 実施可
A8: X-007 | B8: B→K | C8: 大量セット一括投入 | D8: E2Eの滞留・欠落・性能確認 | E8: 多数セット投入→全件処理完了まで監視 | F8: 投入件数と受信/DB/画面件数が整合する | G8: P1 | H8: 条件付き
A9: X-008 | B9: C→K | C9: 通信断→復旧→再送 | D9: E2E復旧性確認 | E9: 送信途中断→復旧→再送→DB/画面照合 | F9: 破損/重複なしで最終的に正しい表示 | G9: P1 | H9: 条件付き
A10: X-009 | B10: B→K | C10: 3ファイルの到着順逆転 | D10: ファイル種別の独立性・関連付け確認 | E10: PROCESS→EVENT→SAMPLING順に投入 | F10: 種別を取り違えず所定DB・画面に反映 | G10: P1 | H10: 実施可
A11: X-010 | B11: C→K | C11: Sender再起動を挟む再送 | D11: 送信管理の永続性確認 | E11: 送信中Sender停止→再起動→処理継続 | F11: 未完了だけ安全に再処理され、画面に重複なし | G11: P1 | H11: 条件付き
A12: X-011 | B12: G→K | C12: Receiver再起動を挟む登録 | D12: 受信/登録管理の永続性確認 | E12: 受信中Receiver停止→再起動→再送/再登録 | F12: 最終DB・画面とSQLite状態が一致 | G12: P1 | H12: 条件付き
... A16: X-015 | B16: B→K | C16: 障害解除後の完全E2E復帰 | D16: 最終的な運用復旧性を確認 | E16: 代表的な通信/DB障害を発生→解除→新規正常セット投入 | F16: 過去障害の影響を引きずらず、新規データが正常に表示 | G16: P1 | H16: 条件付き
